Workbook

Sheet Mercedes
A1: Date | B1: Open | C1: High | D1: Low | E1: Close | F1: Adj Close | G1: Volume
A2: Mar 10, 2026 | B2: 55.38 | C2: 55.84 | D2: 55.11 | E2: 55.44 | F2: 55.44 | G2: 566.496
A3: Mar 9, 2026 | B3: 54.5 | C3: 54.86 | D3: 53.54 | E3: 54.25 | F3: 54.25 | G3: 2,395,578
A4: Mar 2, 2026 | B4: 57 | C4: 57.9 | D4: 54.23 | E4: 54.78 | F4: 54.78 | G4: 13,471,670 | I4: https://finance.yahoo.com/quote/MBG.DE/history/?frequency=1wk
A5: Feb 23, 2026 | B5: 59.27 | C5: 59.51 | D5: 58.21 | E5: 59 | F5: 59 | G5: 10,967,204
A6: Feb 16, 2026 | B6: 57.4 | C6: 60.03 | D6: 57.19 | E6: 59.24 | F6: 59.24 | G6: 10,370,202 | I6: Mercedes-Benz Group AG (MBG.DE)
A7: Feb 9, 2026 | B7: 58.71 | C7: 59.5 | D7: 54.65 | E7: 57.62 | F7: 57.62 | G7: 16,121,673
A8: Feb 2, 2026 | B8: 57.6 | C8: 61.3 | D8: 57.45 | E8: 58.78 | F8: 58.78 | G8: 13,803,710
A9: Jan 26, 2026 | B9: 58.1 | C9: 58.89 | D9: 55.95 | E9: 57.79 | F9: 57.79 | G9: 10,179,576
A10: Jan 19, 2026 | B10: 56.37 | C10: 60.11 | D10: 54.89 | E10: 58.3 | F10: 58.3 | G10: 12,410,831
A11: Jan 12, 2026 | B11: 60.18 | C11: 61.12 | D11: 58.19 | E11: 58.82 | F11: 58.82 | G11: 11,669,786
A12: Jan 5, 2026 | B12: 61.6 | C12: 62.34 | D12: 58.79 | E12: 60.37 | F12: 60.37 | G12: 10,451,462
A13: Dec 29, 2025 | B13: 59.25 | C13: 62.03 | D13: 59.25 | E13: 61.93 | F13: 61.93 | G13: 4,890,034
A14: Dec 22, 2025 | B14: 60.13 | C14: 60.17 | D14: 59.11 | E14: 59.3 | F14: 59.3 | G14: 1,809,422
A15: Dec 15, 2025 | B15: 61.69 | C15: 61.78 | D15: 59.46 | E15: 59.84 | F15: 59.84 | G15: 6,066,903
A16: Dec 8, 2025 | B16: 61.31 | C16: 62.03 | D16: 59.82 | E16: 61.69 | F16: 61.69 | G16: 8,168,263
A17: Dec 1, 2025 | B17: 58.2 | C17: 61.68 | D17: 56.88 | E17: 61.6 | F17: 61.6 | G17: 12,949,490
A18: Nov 24, 2025 | B18: 58.09 | C18: 58.48 | D18: 56.94 | E18: 58.16 | F18: 58.16 | G18: 8,502,451
... A46: May 12, 2025 | B46: 52.11 | C46: 54.51 | D46: 52.05 | E46: 52.5 | F46: 52.5 | G46: 12,856,683
A47: May 8, 2025 | B47: 4.3 Dividend
A48: May 5, 2025 | B48: 53.5 | C48: 54.92 | D48: 49.76 | E48: 51.07 | F48: 47 | G48: 18,223,047
A49: Apr 28, 2025 | B49: 55.05 | C49: 55.57 | D49: 52.12 | E49: 53.3 | F49: 49.05 | G49: 14,599,472
A50: Apr 21, 2025 | B50: 50.23 | C50: 54.82 | D50: 50.16 | E50: 54.59 | F50: 50.24 | G50: 10,533,150
A51: Apr 14, 2025 | B51: 49.12 | C51: 51.16 | D51: 48.67 | E51: 50.23 | F51: 46.23 | G51: 7,900,713
A52: Apr 7, 2025 | B52: 45.66 | C52: 51.46 | D52: 45.6 | E52: 48.19 | F52: 44.36 | G52: 30,136,102
A53: Mar 31, 2025 | B53: 55.13 | C53: 55.19 | D53: 48.31 | E53: 49.06 | F53: 45.16 | G53: 21,152,180
A54: Mar 24, 2025 | B54: 58.36 | C54: 59.81 | D54: 54.75 | E54: 55.75 | F54: 51.31 | G54: 11,720,581
A55: Mar 17, 2025 | B55: 59.97 | C55: 61.55 | D55: 57.7 | E55: 58.36 | F55: 53.71 | G55: 15,929,729
A56: Mar 10, 2025 | B56: 61.74 | C56: 63.17 | D56: 58.72 | E56: 59.97 | F56: 55.19 | G56: 15,177,174

Sheet Dior
A1: Date | B1: Open | C1: High | D1: Low | E1: Close | F1: Adj Close | G1: Volume
A2: Mar 10, 2026 | B2: 484.6 | C2: 486.6 | D2: 480 | E2: 484.6 | F2: 484.6 | G2: 867
A3: Mar 9, 2026 | B3: 468 | C3: 474.2 | D3: 466.4 | E3: 473.8 | F3: 473.8 | G3: 7.439 | I3: https://finance.yahoo.com/quote/CDI.PA/history/?frequency=1wk
A4: Mar 2, 2026 | B4: 490 | C4: 503 | D4: 473.4 | E4: 478.4 | F4: 478.4 | G4: 28.078
A5: Feb 23, 2026 | B5: 524 | C5: 539.5 | D5: 512 | E5: 517 | F5: 517 | G5: 25.744 | I5: Christian Dior SE (CDI.PA)
A6: Feb 16, 2026 | B6: 496.2 | C6: 530 | D6: 492 | E6: 526 | F6: 526 | G6: 24.502
A7: Feb 9, 2026 | B7: 502.5 | C7: 513 | D7: 490 | E7: 492 | F7: 492 | G7: 27.938
A8: Feb 2, 2026 | B8: 512 | C8: 514 | D8: 493.4 | E8: 505 | F8: 505 | G8: 33.938
A9: Jan 26, 2026 | B9: 545.5 | C9: 554.5 | D9: 499.4 | E9: 512 | F9: 512 | G9: 47.63
A10: Jan 19, 2026 | B10: 548.5 | C10: 557.5 | D10: 530.5 | E10: 549.5 | F10: 549.5 | G10: 19.349
A11: Jan 12, 2026 | B11: 605.5 | C11: 610 | D11: 561 | E11: 566 | F11: 566 | G11: 14.77
A12: Jan 5, 2026 | B12: 593 | C12: 607.5 | D12: 578 | E12: 607.5 | F12: 607.5 | G12: 16.375
A13: Dec 29, 2025 | B13: 582 | C13: 604 | D13: 582 | E13: 601.5 | F13: 601.5 | G13: 10.561
A14: Dec 22, 2025 | B14: 582 | C14: 587 | D14: 579 | E14: 581.5 | F14: 581.5 | G14: 8.644
A15: Dec 15, 2025 | B15: 581 | C15: 593.5 | D15: 575.5 | E15: 587 | F15: 587 | G15: 18.656
A16: Dec 8, 2025 | B16: 580.5 | C16: 585 | D16: 570.5 | E16: 580.5 | F16: 580.5 | G16: 9.989
A17: Dec 2, 2025 | B17: 6.05 Dividend
A18: Dec 1, 2025 | B18: 584 | C18: 601 | D18: 579 | E18: 587 | F18: 581.08 | G18: 10.95
A19: Nov 24, 2025 | B19: 588.5 | C19: 591 | D19: 572.5 | E19: 589.5 | F19: 583.56 | G19: 11.093
A20: Nov 17, 2025 | B20: 596 | C20: 596 | D20: 567.5 | E20: 581 | F20: 575.14 | G20: 14.925
A21: Nov 10, 2025 | B21: 573 | C21: 611.5 | D21: 571 | E21: 597.5 | F21: 591.48 | G21: 23.446
A22: Nov 3, 2025 | B22: 566 | C22: 574 | D22: 553.5 | E22: 563 | F22: 557.32 | G22: 10.761
A23: Oct 27, 2025 | B23: 574.5 | C23: 577 | D23: 562.5 | E23: 567.5 | F23: 561.78 | G23: 11.819
A24: Oct 20, 2025 | B24: 563 | C24: 583.5 | D24: 552 | E24: 570 | F24: 564.25 | G24: 20.324
A25: Oct 13, 2025 | B25: 515.5 | C25: 569 | D25: 494.2 | E25: 560 | F25: 554.35 | G25: 27.462
A26: Oct 6, 2025 | B26: 522.5 | C26: 549 | D26: 507 | E26: 511.5 | F26: 506.34 | G26: 20.943
A27: Sep 29, 2025 | B27: 490.2 | C27: 524 | D27: 486.4 | E27: 524 | F27: 518.72 | G27: 18.514
A28: Sep 22, 2025 | B28: 485 | C28: 501 | D28: 477 | E28: 486.2 | F28: 481.3 | G28: 12.255
A29: Sep 15, 2025 | B29: 476.2 | C29: 498 | D29: 474.8 | E29: 486 | F29: 481.1 | G29: 34.359
... A49: Apr 28, 2025 | B49: 462.4 | C49: 467 | D49: 445 | E49: 461.6 | F49: 456.95 | G49: 22.057
A50: Apr 24, 2025 | B50: 7.5 Dividend
A51: Apr 21, 2025 | B51: 444.4 | C51: 474 | D51: 434.4 | E51: 460 | F51: 448.02 | G51: 25.61
A52: Apr 14, 2025 | B52: 490.8 | C52: 495.2 | D52: 443.8 | E52: 444.4 | F52: 432.83 | G52: 29.34
A53: Apr 7, 2025 | B53: 454.6 | C53: 520.5 | D53: 445.6 | E53: 479.8 | F53: 467.31 | G53: 51.959
A54: Mar 31, 2025 | B54: 529 | C54: 540 | D54: 480.2 | E54: 488.4 | F54: 475.68 | G54: 34.054
A55: Mar 24, 2025 | B55: 560 | C55: 563 | D55: 540.5 | E55: 541.5 | F55: 527.4 | G55: 25.786
A56: Mar 17, 2025 | B56: 560.5 | C56: 567.5 | D56: 549 | E56: 557 | F56: 542.5 | G56: 26.483
A57: Mar 10, 2025 | B57: 588.5 | C57: 589 | D57: 553.5 | E57: 559.5 | F57: 544.93 | G57: 25.451

Sheet Combine
A1: Date | B1: MBG.DE | C1: CDI.PA | D1: Weekly return MBG.DE | E1: Weekly return CDI.PA
A2: Mar 10, 2026 | B2: =IFERROR(VLOOKUP(A2,Mercedes!A:F,6,FALSE),"") -> 55.44 | C2: =IFERROR(VLOOKUP(A2,Dior!A:F,6,FALSE),"") -> 484.6 | D2: =IFERROR(B2/B3-1,"") -> 0.021935484 | E2: =IFERROR(C2/C3-1,"") -> 0.022794428 | H2: Data Descriptions
A3: Mar 9, 2026 | B3: =IFERROR(VLOOKUP(A3,Mercedes!A:F,6,FALSE),"") -> 54.25 | C3: =IFERROR(VLOOKUP(A3,Dior!A:F,6,FALSE),"") -> 473.8 | D3: =IFERROR(B3/B4-1,"") -> -0.0096750639 | E3: =IFERROR(C3/C4-1,"") -> -0.0096153846
A4: Mar 2, 2026 | B4: =IFERROR(VLOOKUP(A4,Mercedes!A:F,6,FALSE),"") -> 54.78 | C4: =IFERROR(VLOOKUP(A4,Dior!A:F,6,FALSE),"") -> 478.4 | D4: =IFERROR(B4/B5-1,"") -> -0.071525424 | E4: =IFERROR(C4/C5-1,"") -> -0.074661509 | I4: MBG.DE | J4: CDI.PA
A5: Feb 23, 2026 | B5: =IFERROR(VLOOKUP(A5,Mercedes!A:F,6,FALSE),"") -> 59 | C5: =IFERROR(VLOOKUP(A5,Dior!A:F,6,FALSE),"") -> 517 | D5: =IFERROR(B5/B6-1,"") -> -0.0040513167 | E5: =IFERROR(C5/C6-1,"") -> -0.017110266 | H5: Max | I5: =MAX(D2:D55) -> 0.086740212 | J5: =MAX(E:E) -> 0.094817711
A6: Feb 16, 2026 | B6: =IFERROR(VLOOKUP(A6,Mercedes!A:F,6,FALSE),"") -> 59.24 | C6: =IFERROR(VLOOKUP(A6,Dior!A:F,6,FALSE),"") -> 526 | D6: =IFERROR(B6/B7-1,"") -> 0.028115238 | E6: =IFERROR(C6/C7-1,"") -> 0.069105691 | H6: MIn | I6: =MIN(D:D) -> -1 | J6: =MIN(E:E) -> -0.098065984
A7: Feb 9, 2026 | B7: =IFERROR(VLOOKUP(A7,Mercedes!A:F,6,FALSE),"") -> 57.62 | C7: =IFERROR(VLOOKUP(A7,Dior!A:F,6,FALSE),"") -> 492 | D7: =IFERROR(B7/B8-1,"") -> -0.019734604 | E7: =IFERROR(C7/C8-1,"") -> -0.025742574 | H7: Range | I7: =I5-I6 -> 1.0867402 | J7: =J5-J6 -> 0.1928837
A8: Feb 2, 2026 | B8: =IFERROR(VLOOKUP(A8,Mercedes!A:F,6,FALSE),"") -> 58.78 | C8: =IFERROR(VLOOKUP(A8,Dior!A:F,6,FALSE),"") -> 505 | D8: =IFERROR(B8/B9-1,"") -> 0.017130992 | E8: =IFERROR(C8/C9-1,"") -> -0.013671875
A9: Jan 26, 2026 | B9: =IFERROR(VLOOKUP(A9,Mercedes!A:F,6,FALSE),"") -> 57.79 | C9: =IFERROR(VLOOKUP(A9,Dior!A:F,6,FALSE),"") -> 512 | D9: =IFERROR(B9/B10-1,"") -> -0.0087478559 | E9: =IFERROR(C9/C10-1,"") -> -0.068243858 | H9: Q3 | I9: =_xlfn.PERCENTILE.INC(D:D,0.75) -> 0.030461596 | J9: =_xlfn.PERCENTILE.INC(E:E,0.75) -> 0.019254869
A10: Jan 19, 2026 | B10: =IFERROR(VLOOKUP(A10,Mercedes!A:F,6,FALSE),"") -> 58.3 | C10: =IFERROR(VLOOKUP(A10,Dior!A:F,6,FALSE),"") -> 549.5 | D10: =IFERROR(B10/B11-1,"") -> -0.0088405304 | E10: =IFERROR(C10/C11-1,"") -> -0.029151943 | H10: Q1 | I10: =_xlfn.PERCENTILE.INC(D:D,0.25) -> -0.026816452 | J10: =_xlfn.PERCENTILE.INC(E:E,0.25) -> -0.023699901
A11: Jan 12, 2026 | B11: =IFERROR(VLOOKUP(A11,Mercedes!A:F,6,FALSE),"") -> 58.82 | C11: =IFERROR(VLOOKUP(A11,Dior!A:F,6,FALSE),"") -> 566 | D11: =IFERROR(B11/B12-1,"") -> -0.025675004 | E11: =IFERROR(C11/C12-1,"") -> -0.068312757 | H11: IQR | I11: =I9-I10 -> 0.057278048 | J11: =J9-J10 -> 0.04295477
A12: Jan 5, 2026 | B12: =IFERROR(VLOOKUP(A12,Mercedes!A:F,6,FALSE),"") -> 60.37 | C12: =IFERROR(VLOOKUP(A12,Dior!A:F,6,FALSE),"") -> 607.5 | D12: =IFERROR(B12/B13-1,"") -> -0.02518973 | E12: =IFERROR(C12/C13-1,"") -> 0.0099750623 | H12: Fence | I12: =I11*1.5 -> 0.085917072 | J12: =J11*1.5 -> 0.064432155
A13: Dec 29, 2025 | B13: =IFERROR(VLOOKUP(A13,Mercedes!A:F,6,FALSE),"") -> 61.93 | C13: =IFERROR(VLOOKUP(A13,Dior!A:F,6,FALSE),"") -> 601.5 | D13: =IFERROR(B13/B14-1,"") -> 0.044350759 | E13: =IFERROR(C13/C14-1,"") -> 0.034393809 | H13: Upper Fence | I13: =I9+I12 -> 0.11637867 | J13: =J9+J12 -> 0.083687024
A14: Dec 22, 2025 | B14: =IFERROR(VLOOKUP(A14,Mercedes!A:F,6,FALSE),"") -> 59.3 | C14: =IFERROR(VLOOKUP(A14,Dior!A:F,6,FALSE),"") -> 581.5 | D14: =IFERROR(B14/B15-1,"") -> -0.0090240642 | E14: =IFERROR(C14/C15-1,"") -> -0.0093696763 | H14: Lower fence | I14: =I10-I12 -> -0.11273352 | J14: =J10-J12 -> -0.088132057
A15: Dec 15, 2025 | B15: =IFERROR(VLOOKUP(A15,Mercedes!A:F,6,FALSE),"") -> 59.84 | C15: =IFERROR(VLOOKUP(A15,Dior!A:F,6,FALSE),"") -> 587 | D15: =IFERROR(B15/B16-1,"") -> -0.029988653 | E15: =IFERROR(C15/C16-1,"") -> 0.011197244 | H15: Mean | I15: =AVERAGE(D:D) -> -0.019974898 | J15: =AVERAGE(E:E) -> -0.0019434423
A16: Dec 8, 2025 | B16: =IFERROR(VLOOKUP(A16,Mercedes!A:F,6,FALSE),"") -> 61.69 | C16: =IFERROR(VLOOKUP(A16,Dior!A:F,6,FALSE),"") -> 580.5 | D16: =IFERROR(B16/B17-1,"") -> 0.001461039 | E16: =IFERROR(C16/C17-1,"") -> -0.00099814139 | H16: Z min | I16: =(I6-I15)/I20 -> -6.8246332 | J16: =(J6-J15)/J20 -> -2.4537912
A17: Dec 1, 2025 | B17: =IFERROR(VLOOKUP(A17,Mercedes!A:F,6,FALSE),"") -> 61.6 | C17: =IFERROR(VLOOKUP(A17,Dior!A:F,6,FALSE),"") -> 581.08 | D17: =IFERROR(B17/B18-1,"") -> 0.05914718 | E17: =IFERROR(C17/C18-1,"") -> -0.0042497772 | H17: Zmax | I17: =(I5-I15)/I20 -> 0.74313554 | J17: =(J5-J15)/J20 -> 2.4700935
A18: Nov 24, 2025 | B18: =IFERROR(VLOOKUP(A18,Mercedes!A:F,6,FALSE),"") -> 58.16 | C18: =IFERROR(VLOOKUP(A18,Dior!A:F,6,FALSE),"") -> 583.56 | D18: =IFERROR(B18/B19-1,"") -> 0.019992985 | E18: =IFERROR(C18/C19-1,"") -> 0.014639914 | H18: Mean absolute deviation | I18: =AVEDEV(D:D)*55/54 -> 0.054600632 | J18: =AVEDEV(E:E)*55/54 -> 0.029934404
A19: Nov 17, 2025 | B19: =IFERROR(VLOOKUP(A19,Mercedes!A:F,6,FALSE),"") -> 57.02 | C19: =IFERROR(VLOOKUP(A19,Dior!A:F,6,FALSE),"") -> 575.14 | D19: =IFERROR(B19/B20-1,"") -> -0.042646071 | E19: =IFERROR(C19/C20-1,"") -> -0.027625617 | H19: Sample Varience | I19: =VAR(D:D) -> 0.020621287 | J19: =VAR(E:E) -> 0.0015345296
A20: Nov 10, 2025 | B20: =IFERROR(VLOOKUP(A20,Mercedes!A:F,6,FALSE),"") -> 59.56 | C20: =IFERROR(VLOOKUP(A20,Dior!A:F,6,FALSE),"") -> 591.48 | D20: =IFERROR(B20/B21-1,"") -> 0.023543564 | E20: =IFERROR(C20/C21-1,"") -> 0.061293332 | H20: Sample Standard deviation | I20: =_xlfn.STDEV.S(D:D) -> 0.14360114 | J20: =_xlfn.STDEV.S(E:E) -> 0.039173073
A21: Nov 3, 2025 | B21: =IFERROR(VLOOKUP(A21,Mercedes!A:F,6,FALSE),"") -> 58.19 | C21: =IFERROR(VLOOKUP(A21,Dior!A:F,6,FALSE),"") -> 557.32 | D21: =IFERROR(B21/B22-1,"") -> 0.035225049 | E21: =IFERROR(C21/C22-1,"") -> -0.0079390509 | H21: CV | I21: =I20/I15 -> -7.1890799 | J21: =J20/J15 -> -20.15654
A22: Oct 27, 2025 | B22: =IFERROR(VLOOKUP(A22,Mercedes!A:F,6,FALSE),"") -> 56.21 | C22: =IFERROR(VLOOKUP(A22,Dior!A:F,6,FALSE),"") -> 561.78 | D22: =IFERROR(B22/B23-1,"") -> 0.045767442 | E22: =IFERROR(C22/C23-1,"") -> -0.0043774922
A23: Oct 20, 2025 | B23: =IFERROR(VLOOKUP(A23,Mercedes!A:F,6,FALSE),"") -> 53.75 | C23: =IFERROR(VLOOKUP(A23,Dior!A:F,6,FALSE),"") -> 564.25 | D23: =IFERROR(B23/B24-1,"") -> 0.0071201049 | E23: =IFERROR(C23/C24-1,"") -> 0.017858753 | H23: Covariance | I23: =_xlfn.COVARIANCE.S(D:D,E:E) -> 0.00095706809
A24: Oct 13, 2025 | B24: =IFERROR(VLOOKUP(A24,Mercedes!A:F,6,FALSE),"") -> 53.37 | C24: =IFERROR(VLOOKUP(A24,Dior!A:F,6,FALSE),"") -> 554.35 | D24: =IFERROR(B24/B25-1,"") -> 0.0031954887 | E24: =IFERROR(C24/C25-1,"") -> 0.094817711 | H24: Correlation | I24: =CORREL(D:D,E:E) -> 0.57094695
A25: Oct 6, 2025 | B25: =IFERROR(VLOOKUP(A25,Mercedes!A:F,6,FALSE),"") -> 53.2 | C25: =IFERROR(VLOOKUP(A25,Dior!A:F,6,FALSE),"") -> 506.34 | D25: =IFERROR(B25/B26-1,"") -> -0.039884497 | E25: =IFERROR(C25/C26-1,"") -> -0.02386644
A26: Sep 29, 2025 | B26: =IFERROR(VLOOKUP(A26,Mercedes!A:F,6,FALSE),"") -> 55.41 | C26: =IFERROR(VLOOKUP(A26,Dior!A:F,6,FALSE),"") -> 518.72 | D26: =IFERROR(B26/B27-1,"") -> 0.039197299 | E26: =IFERROR(C26/C27-1,"") -> 0.077747766
A27: Sep 22, 2025 | B27: =IFERROR(VLOOKUP(A27,Mercedes!A:F,6,FALSE),"") -> 53.32 | C27: =IFERROR(VLOOKUP(A27,Dior!A:F,6,FALSE),"") -> 481.3 | D27: =IFERROR(B27/B28-1,"") -> 0.035742036 | E27: =IFERROR(C27/C28-1,"") -> 0.00041571399
A28: Sep 15, 2025 | B28: =IFERROR(VLOOKUP(A28,Mercedes!A:F,6,FALSE),"") -> 51.48 | C28: =IFERROR(VLOOKUP(A28,Dior!A:F,6,FALSE),"") -> 481.1 | D28: =IFERROR(B28/B29-1,"") -> -0.0040626814 | E28: =IFERROR(C28/C29-1,"") -> 0.030545797
A29: Sep 8, 2025 | B29: =IFERROR(VLOOKUP(A29,Mercedes!A:F,6,FALSE),"") -> 51.69 | C29: =IFERROR(VLOOKUP(A29,Dior!A:F,6,FALSE),"") -> 466.84 | D29: =IFERROR(B29/B30-1,"") -> -0.02324263 | E29: =IFERROR(C29/C30-1,"") -> -0.00085609109
A30: Sep 1, 2025 | B30: =IFERROR(VLOOKUP(A30,Mercedes!A:F,6,FALSE),"") -> 52.92 | C30: =IFERROR(VLOOKUP(A30,Dior!A:F,6,FALSE),"") -> 467.24 | D30: =IFERROR(B30/B31-1,"") -> -0.0080599813 | E30: =IFERROR(C30/C31-1,"") -> -0.020748627
A31: Aug 25, 2025 | B31: =IFERROR(VLOOKUP(A31,Mercedes!A:F,6,FALSE),"") -> 53.35 | C31: =IFERROR(VLOOKUP(A31,Dior!A:F,6,FALSE),"") -> 477.14 | D31: =IFERROR(B31/B32-1,"") -> -0.032462822 | E31: =IFERROR(C31/C32-1,"") -> 0.01902911
A32: Aug 18, 2025 | B32: =IFERROR(VLOOKUP(A32,Mercedes!A:F,6,FALSE),"") -> 55.14 | C32: =IFERROR(VLOOKUP(A32,Dior!A:F,6,FALSE),"") -> 468.23 | D32: =IFERROR(B32/B33-1,"") -> 0.030461596 | E32: =IFERROR(C32/C33-1,"") -> 0.038180972
A33: Aug 11, 2025 | B33: =IFERROR(VLOOKUP(A33,Mercedes!A:F,6,FALSE),"") -> 53.51 | C33: =IFERROR(VLOOKUP(A33,Dior!A:F,6,FALSE),"") -> 451.01 | D33: =IFERROR(B33/B34-1,"") -> 0.026669225 | E33: =IFERROR(C33/C34-1,"") -> 0.016520916
A34: Aug 4, 2025 | B34: =IFERROR(VLOOKUP(A34,Mercedes!A:F,6,FALSE),"") -> 52.12 | C34: =IFERROR(VLOOKUP(A34,Dior!A:F,6,FALSE),"") -> 443.68 | D34: =IFERROR(B34/B35-1,"") -> 0.061507128 | E34: =IFERROR(C34/C35-1,"") -> 0.017708047
A35: Jul 28, 2025 | B35: =IFERROR(VLOOKUP(A35,Mercedes!A:F,6,FALSE),"") -> 49.1 | C35: =IFERROR(VLOOKUP(A35,Dior!A:F,6,FALSE),"") -> 435.96 | D35: =IFERROR(B35/B36-1,"") -> -0.11515588 | E35: =IFERROR(C35/C36-1,"") -> -0.055750487
A36: Jul 21, 2025 | B36: =IFERROR(VLOOKUP(A36,Mercedes!A:F,6,FALSE),"") -> 55.49 | C36: =IFERROR(VLOOKUP(A36,Dior!A:F,6,FALSE),"") -> 461.7 | D36: =IFERROR(B36/B37-1,"") -> 0.081044224 | E36: =IFERROR(C36/C37-1,"") -> 0.038765271
... A56: Mar 10, 2025 | B56: =IFERROR(VLOOKUP(A56,Mercedes!A:F,6,FALSE),"") -> 55.19 | C56: =IFERROR(VLOOKUP(A56,Dior!A:F,6,FALSE),"") -> 544.93 | D56: =IFERROR(B56/B57-1,"") | E56: =IFERROR(C56/C57-1,"")

Sheet S&P 500
A1: Date | B1: Open | C1: High | D1: Low | E1: Close | F1: Adj Close | G1: Volume | P1: Date | Q1: Adj Close | R1: weekly return
A2: Mar 9 2026 | B2: 6699.8 | C2: 6810.44 | D2: 6636.04 | E2: 6795.99 | F2: 6795.99 | G2: 6709410000 | P2: Mar 9, 2026 | Q2: 6795.99 | R2: =Q2/Q3-1 -> 0.0083041297
A3: Mar 2 2026 | B3: 6824.36 | C3: 6901.01 | D3: 6710.42 | E3: 6740.02 | F3: 6740.02 | G3: 29555750000 | I3: https://finance,yahoo,com/quote/%5EGSPC/history/?frequency=1wk | P3: Mar 2, 2026 | Q3: 6740.02 | R3: =Q3/Q4-1 -> -0.020186426
A4: Feb 23 2026 | B4: 6901.25 | C4: 6952.51 | D4: 6815.43 | E4: 6878.88 | F4: 6878.88 | G4: 28787710000 | P4: Feb 23, 2026 | Q4: 6878.88 | R4: =Q4/Q5-1 -> -0.0044330206
A5: Feb 16 2026 | B5: 6819.86 | C5: 6915.86 | D5: 6775.5 | E5: 6909.51 | F5: 6909.51 | G5: 21100810000 | I5: S&P 500 (^GSPC) | P5: Feb 16, 2026 | Q5: 6909.51 | R5: =Q5/Q6-1 -> 0.010728229
A6: Feb 9 2026 | B6: 6917.26 | C6: 6993.48 | D6: 6794.55 | E6: 6836.17 | F6: 6836.17 | G6: 30258780000 | P6: Feb 9, 2026 | Q6: 6836.17 | R6: =Q6/Q7-1 -> -0.013866971
A7: Feb 2 2026 | B7: 6916.64 | C7: 6993.08 | D7: 6780.13 | E7: 6932.3 | F7: 6932.3 | G7: 33538260000 | P7: Feb 2, 2026 | Q7: 6932.3 | R7: =Q7/Q8-1 -> -0.00096987619
A8: Jan 26 2026 | B8: 6923.23 | C8: 7002.28 | D8: 6870.8 | E8: 6939.03 | F8: 6939.03 | G8: 29382560000 | P8: Jan 26, 2026 | Q8: 6939.03 | R8: =Q8/Q9-1 -> 0.0033865415
A9: Jan 19 2026 | B9: 6865.24 | C9: 6934.75 | D9: 6789.05 | E9: 6915.61 | F9: 6915.61 | G9: 21784530000 | P9: Jan 19, 2026 | Q9: 6915.61 | R9: =Q9/Q10-1 -> -0.0035158451
A10: Jan 12 2026 | B10: 6944.12 | C10: 6986.33 | D10: 6885.74 | E10: 6940.01 | F10: 6940.01 | G10: 26112200000 | P10: Jan 12, 2026 | Q10: 6940.01 | R10: =Q10/Q11-1 -> -0.0037710227
A11: Jan 5 2026 | B11: 6892.19 | C11: 6978.36 | D11: 6891.56 | E11: 6966.28 | F11: 6966.28 | G11: 26993190000 | P11: Jan 5, 2026 | Q11: 6966.28 | R11: =Q11/Q12-1 -> 0.015719249
A12: Dec 29 2025 | B12: 6903.6 | C12: 6920.21 | D12: 6824.31 | E12: 6858.47 | F12: 6858.47 | G12: 14297630000 | P12: Dec 29, 2025 | Q12: 6858.47 | R12: =Q12/Q13-1 -> -0.010313221
A13: Dec 22 2025 | B13: 6865.21 | C13: 6945.77 | D13: 6855.74 | E13: 6929.94 | F13: 6929.94 | G13: 12670410000 | P13: Dec 22, 2025 | Q13: 6929.94 | R13: =Q13/Q14-1 -> 0.013964445
A14: Dec 15 2025 | B14: 6860.19 | C14: 6861.59 | D14: 6720.43 | E14: 6834.5 | F14: 6834.5 | G14: 28736560000 | P14: Dec 15, 2025 | Q14: 6834.5 | R14: =Q14/Q15-1 -> 0.0010384611
A15: Dec 8 2025 | B15: 6875.2 | C15: 6903.46 | D15: 6801.79 | E15: 6827.41 | F15: 6827.41 | G15: 24722970000 | P15: Dec 8, 2025 | Q15: 6827.41 | R15: =Q15/Q16-1 -> -0.0062572776
A16: Dec 1 2025 | B16: 6812.3 | C16: 6895.78 | D16: 6799.94 | E16: 6870.4 | F16: 6870.4 | G16: 23685440000 | P16: Dec 1, 2025 | Q16: 6870.4 | R16: =Q16/Q17-1 -> 0.0031113622
A17: Nov 24 2025 | B17: 6636.54 | C17: 6850.86 | D17: 6630.7 | E17: 6849.09 | F17: 6849.09 | G17: 18086610000 | P17: Nov 24, 2025 | Q17: 6849.09 | R17: =Q17/Q18-1 -> 0.037270994
... A53: Mar 17 2025 | B53: 5635.6 | C53: 5715.33 | D53: 5597.76 | E53: 5667.56 | F53: 5667.56 | G53: 28404010000 | P53: Mar 24, 2025 | Q53: 5667.56 | R53: =Q53/Q54-1 -> 0.005075422
A54: Mar 10 2025 | B54: 5705.37 | C54: 5705.37 | D54: 5504.65 | E54: 5638.94 | F54: 5638.94 | G54: 27732600000 | P54: Mar 17, 2025 | Q54: 5638.94
P55: Mar 10, 2025

Sheet Sharpe Ratio and Comparison of 
A2: Sharpe Ratio | B2: =(Combine!I15-B5)/Combine!I20 -> -0.14440301 | C2: =(Combine!J15-B5)/Combine!J20 -> -0.069052045
A4: One year T.Bill | B4: 0.0396
A5: One week T.Bill | B5: =B4/52 -> 0.00076153846
A9: Comparison of risk (Variance)
A10: Mercedes | B10: X
A11: Dior | B11: Y
A12: H0: | B12: σ^2(Y)​=σ^2(X)​
A13: HA: | B13: σ^2(Y) >​σ^2(X)​
A15: n | B15: 54
A16: df1 | B16: 53
A17: df2 | B17: 53
A18: F(df1, df2) | B18: S(Y)/S(X)
A19: F(53, 53) | B19: =Combine!J19/Combine!I19 -> 0.074414831
A20: P | B20: =_xlfn.F.DIST.RT(B19,53,53) -> 1
A21: Fails to reject H0 at 5% significane level

Sheet Regression
A1: Date | B1: Mercedes | C1: S&P 500
A2: Mar 10, 2026 | B2: =IFERROR(VLOOKUP(A2,Combine!A:E,4,0),"") -> 0.021935484 | C2: 0
A3: Mar 9, 2026 | B3: =IFERROR(VLOOKUP(A3,Combine!A:E,4,0),"") -> -0.0096750639 | C3: =VLOOKUP(A3,'S&P 500'!P:R,3,0) -> 0.0083041297
A4: Mar 2, 2026 | B4: =IFERROR(VLOOKUP(A4,Combine!A:E,4,0),"") -> -0.071525424 | C4: =VLOOKUP(A4,'S&P 500'!P:R,3,0) -> -0.020186426
A5: Feb 23, 2026 | B5: =IFERROR(VLOOKUP(A5,Combine!A:E,4,0),"") -> -0.0040513167 | C5: =VLOOKUP(A5,'S&P 500'!P:R,3,0) -> -0.0044330206
A6: Feb 16, 2026 | B6: =IFERROR(VLOOKUP(A6,Combine!A:E,4,0),"") -> 0.028115238 | C6: =VLOOKUP(A6,'S&P 500'!P:R,3,0) -> 0.010728229
A7: Feb 9, 2026 | B7: =IFERROR(VLOOKUP(A7,Combine!A:E,4,0),"") -> -0.019734604 | C7: =VLOOKUP(A7,'S&P 500'!P:R,3,0) -> -0.013866971
A8: Feb 2, 2026 | B8: =IFERROR(VLOOKUP(A8,Combine!A:E,4,0),"") -> 0.017130992 | C8: =VLOOKUP(A8,'S&P 500'!P:R,3,0) -> -0.00096987619
A9: Jan 26, 2026 | B9: =IFERROR(VLOOKUP(A9,Combine!A:E,4,0),"") -> -0.0087478559 | C9: =VLOOKUP(A9,'S&P 500'!P:R,3,0) -> 0.0033865415
A10: Jan 19, 2026 | B10: =IFERROR(VLOOKUP(A10,Combine!A:E,4,0),"") -> -0.0088405304 | C10: =VLOOKUP(A10,'S&P 500'!P:R,3,0) -> -0.0035158451
A11: Jan 12, 2026 | B11: =IFERROR(VLOOKUP(A11,Combine!A:E,4,0),"") -> -0.025675004 | C11: =VLOOKUP(A11,'S&P 500'!P:R,3,0) -> -0.0037710227 | G11: ВЫВОД ИТОГОВ
A12: Jan 5, 2026 | B12: =IFERROR(VLOOKUP(A12,Combine!A:E,4,0),"") -> -0.02518973 | C12: =VLOOKUP(A12,'S&P 500'!P:R,3,0) -> 0.015719249
A13: Dec 29, 2025 | B13: =IFERROR(VLOOKUP(A13,Combine!A:E,4,0),"") -> 0.044350759 | C13: =VLOOKUP(A13,'S&P 500'!P:R,3,0) -> -0.010313221 | G13: Регрессионная статистика
A14: Dec 22, 2025 | B14: =IFERROR(VLOOKUP(A14,Combine!A:E,4,0),"") -> -0.0090240642 | C14: =VLOOKUP(A14,'S&P 500'!P:R,3,0) -> 0.013964445 | G14: Множественный R | H14: 0.13180334
A15: Dec 15, 2025 | B15: =IFERROR(VLOOKUP(A15,Combine!A:E,4,0),"") -> -0.029988653 | C15: =VLOOKUP(A15,'S&P 500'!P:R,3,0) -> 0.0010384611 | G15: R-квадрат | H15: 0.01737212
A16: Dec 8, 2025 | B16: =IFERROR(VLOOKUP(A16,Combine!A:E,4,0),"") -> 0.001461039 | C16: =VLOOKUP(A16,'S&P 500'!P:R,3,0) -> -0.0062572776 | G16: Нормированный R-квадрат | H16: -0.0015245703
A17: Dec 1, 2025 | B17: =IFERROR(VLOOKUP(A17,Combine!A:E,4,0),"") -> 0.05914718 | C17: =VLOOKUP(A17,'S&P 500'!P:R,3,0) -> 0.0031113622 | G17: Стандартная ошибка | H17: 0.022407823
A18: Nov 24, 2025 | B18: =IFERROR(VLOOKUP(A18,Combine!A:E,4,0),"") -> 0.019992985 | C18: =VLOOKUP(A18,'S&P 500'!P:R,3,0) -> 0.037270994 | G18: Наблюдения | H18: 54
A19: Nov 17, 2025 | B19: =IFERROR(VLOOKUP(A19,Combine!A:E,4,0),"") -> -0.042646071 | C19: =VLOOKUP(A19,'S&P 500'!P:R,3,0) -> -0.019471021
A20: Nov 10, 2025 | B20: =IFERROR(VLOOKUP(A20,Combine!A:E,4,0),"") -> 0.023543564 | C20: =VLOOKUP(A20,'S&P 500'!P:R,3,0) -> 0.00078914517 | G20: Дисперсионный анализ
A21: Nov 3, 2025 | B21: =IFERROR(VLOOKUP(A21,Combine!A:E,4,0),"") -> 0.035225049 | C21: =VLOOKUP(A21,'S&P 500'!P:R,3,0) -> -0.016286074 | H21: df | I21: SS | J21: MS | K21: F | L21: Значимость F
A22: Oct 27, 2025 | B22: =IFERROR(VLOOKUP(A22,Combine!A:E,4,0),"") -> 0.045767442 | C22: =VLOOKUP(A22,'S&P 500'!P:R,3,0) -> 0.0071425521 | G22: Регрессия | H22: 1 | I22: 0.00046160065 | J22: 0.00046160065 | K22: 0.91932078 | L22: 0.34209038
A23: Oct 20, 2025 | B23: =IFERROR(VLOOKUP(A23,Combine!A:E,4,0),"") -> 0.0071201049 | C23: =VLOOKUP(A23,'S&P 500'!P:R,3,0) -> 0.019159635 | G23: Остаток | H23: 52 | I23: 0.026109748 | J23: 0.00050211054
A24: Oct 13, 2025 | B24: =IFERROR(VLOOKUP(A24,Combine!A:E,4,0),"") -> 0.0031954887 | C24: =VLOOKUP(A24,'S&P 500'!P:R,3,0) -> 0.01701638 | G24: Итого | H24: 53 | I24: 0.026571349
A25: Oct 6, 2025 | B25: =IFERROR(VLOOKUP(A25,Combine!A:E,4,0),"") -> -0.039884497 | C25: =VLOOKUP(A25,'S&P 500'!P:R,3,0) -> -0.024312851
A26: Sep 29, 2025 | B26: =IFERROR(VLOOKUP(A26,Combine!A:E,4,0),"") -> 0.039197299 | C26: =VLOOKUP(A26,'S&P 500'!P:R,3,0) -> 0.010850881 | H26: Коэффициенты | I26: Стандартная ошибка | J26: t-статистика | K26: P-Значение | L26: Нижние 95% | M26: Верхние 95% | N26: Нижние 95,0% | O26: Верхние 95,0%
A27: Sep 22, 2025 | B27: =IFERROR(VLOOKUP(A27,Combine!A:E,4,0),"") -> 0.035742036 | C27: =VLOOKUP(A27,'S&P 500'!P:R,3,0) -> -0.0031000726 | G27: Y-пересечение | H27: 0.0041176557 | I27: 0.0030786772 | J27: 1.3374756 | K27: 0.18688829 | L27: -0.002060162 | M27: 0.010295473 | N27: -0.002060162 | O27: 0.010295473
A28: Sep 15, 2025 | B28: =IFERROR(VLOOKUP(A28,Combine!A:E,4,0),"") -> -0.0040626814 | C28: =VLOOKUP(A28,'S&P 500'!P:R,3,0) -> 0.012160764 | G28: Mercedes | H28: 0.020744089 | I28: 0.021635195 | J28: 0.95881217 | K28: 0.34209038 | L28: -0.022670107 | M28: 0.064158284 | N28: -0.022670107 | O28: 0.064158284
A29: Sep 8, 2025 | B29: =IFERROR(VLOOKUP(A29,Combine!A:E,4,0),"") -> -0.02324263 | C29: =VLOOKUP(A29,'S&P 500'!P:R,3,0) -> 0.015858983
A30: Sep 1, 2025 | B30: =IFERROR(VLOOKUP(A30,Combine!A:E,4,0),"") -> -0.0080599813 | C30: =VLOOKUP(A30,'S&P 500'!P:R,3,0) -> 0.0032877934
A31: Aug 25, 2025 | B31: =IFERROR(VLOOKUP(A31,Combine!A:E,4,0),"") -> -0.032462822 | C31: =VLOOKUP(A31,'S&P 500'!P:R,3,0) -> -0.0010283118
A32: Aug 18, 2025 | B32: =IFERROR(VLOOKUP(A32,Combine!A:E,4,0),"") -> 0.030461596 | C32: =VLOOKUP(A32,'S&P 500'!P:R,3,0) -> 0.0026527954
A33: Aug 11, 2025 | B33: =IFERROR(VLOOKUP(A33,Combine!A:E,4,0),"") -> 0.026669225 | C33: =VLOOKUP(A33,'S&P 500'!P:R,3,0) -> 0.0094452574
A34: Aug 4, 2025 | B34: =IFERROR(VLOOKUP(A34,Combine!A:E,4,0),"") -> 0.061507128 | C34: =VLOOKUP(A34,'S&P 500'!P:R,3,0) -> 0.024276973
A35: Jul 28, 2025 | B35: =IFERROR(VLOOKUP(A35,Combine!A:E,4,0),"") -> -0.11515588 | C35: =VLOOKUP(A35,'S&P 500'!P:R,3,0) -> -0.023577788
A36: Jul 21, 2025 | B36: =IFERROR(VLOOKUP(A36,Combine!A:E,4,0),"") -> 0.081044224 | C36: =VLOOKUP(A36,'S&P 500'!P:R,3,0) -> 0.014586797
A37: Jul 14, 2025 | B37: =IFERROR(VLOOKUP(A37,Combine!A:E,4,0),"") -> -0.033515346 | C37: =VLOOKUP(A37,'S&P 500'!P:R,3,0) -> 0.0059171692
A38: Jul 7, 2025 | B38: =IFERROR(VLOOKUP(A38,Combine!A:E,4,0),"") -> 0.060503195 | C38: =VLOOKUP(A38,'S&P 500'!P:R,3,0) -> -0.0031213422
A39: Jun 30, 2025 | B39: =IFERROR(VLOOKUP(A39,Combine!A:E,4,0),"") -> -0.0081204199 | C39: =VLOOKUP(A39,'S&P 500'!P:R,3,0) -> 0.017216717
A40: Jun 23, 2025 | B40: =IFERROR(VLOOKUP(A40,Combine!A:E,4,0),"") -> 0.038247995 | C40: =VLOOKUP(A40,'S&P 500'!P:R,3,0) -> 0.034389327
...
